<?xml version="1.0" ?>
<sdf version='1.9'>
  <model name='ur3e'>
    <joint name='world_joint' type='fixed'>
      <pose relative_to='__model__'>0 0 0 0 0 0</pose>
      <parent>world</parent>
      <child>base_link</child>
    </joint>
    <link name='base_link'>
      <pose relative_to='world_joint'>0 0 0 0 0 0</pose>
      <inertial>
        <pose>0 0 0 0 0 0</pose>
        <mass>2</mass>
        <inertia>
          <ixx>0.0030531654453999999</ixx>
          <ixy>0</ixy>
          <ixz>0</ixz>
          <iyy>0.0030531654453999999</iyy>
          <iyz>0</iyz>
          <izz>0.0056249999999999998</izz>
        </inertia>
      </inertial>
      <collision name='base_link_collision'>
        <pose>0 0 0 0 0 0</pose>
        <geometry>
          <mesh>
            <scale>1 1 1</scale>
            <uri>meshes/collision/base.stl</uri>
          </mesh>
        </geometry>
      </collision>
      <visual name='base_link_visual'>
        <pose>0 0 0 0 0 0</pose>
        <geometry>
          <mesh>
            <scale>1 1 1</scale>
            <uri>meshes/visual/base.dae</uri>
          </mesh>
        </geometry>
      </visual>
    </link>
    <joint name='shoulder_pan_joint' type='revolute'>
      <pose relative_to='base_link'>0 0 0.152 0 0 0</pose>
      <parent>base_link</parent>
      <child>shoulder_link</child>
      <axis>
        <xyz>0 0 1</xyz>
        <limit>
          <lower>-3.1415926535900001</lower>
          <upper>3.1415926535900001</upper>
          <effort>330</effort>
          <velocity>3.1400000000000001</velocity>
        </limit>
        <dynamics>
          <damping>0</damping>
          <friction>0</friction>
          <spring_reference>0</spring_reference>
          <spring_stiffness>0</spring_stiffness>
        </dynamics>
      </axis>
    </joint>
    <link name='shoulder_link'>
      <pose relative_to='shoulder_pan_joint'>0 0 0 0 0 0</pose>
      <inertial>
        <pose>0 0 0 0 0 0</pose>
        <mass>2</mass>
        <inertia>
          <ixx>0.0080931634294000004</ixx>
          <ixy>0</ixy>
          <ixz>0</ixz>
          <iyy>0.0080931634294000004</iyy>
          <iyz>0</iyz>
          <izz>0.0056249999999999998</izz>
        </inertia>
      </inertial>
      <collision name='shoulder_link_collision'>
        <pose>0 0 0 0 0 0</pose>
        <geometry>
          <mesh>
            <scale>1 1 1</scale>
            <uri>meshes/collision/shoulder.stl</uri>
          </mesh>
        </geometry>
        <surface>
          <contact>
            <ode/>
          </contact>
          <friction>
            <ode/>
          </friction>
        </surface>
      </collision>
      <visual name='shoulder_link_visual'>
        <pose>0 0 0 0 0 0</pose>
        <geometry>
          <mesh>
            <scale>1 1 1</scale>
            <uri>meshes/visual/shoulder.dae</uri>
          </mesh>
        </geometry>
      </visual>
      <self_collide>true</self_collide>
    </link>
    <joint name='shoulder_lift_joint' type='revolute'>
      <pose relative_to='shoulder_link'>0 0.12 0 0 1.570796326794897 0</pose>
      <parent>shoulder_link</parent>
      <child>upper_arm_link</child>
      <axis>
        <xyz>0 1 0</xyz>
        <limit>
          <lower>-3.1415926535900001</lower>
          <upper>3.1415926535900001</upper>
          <effort>330</effort>
          <velocity>3.1400000000000001</velocity>
        </limit>
        <dynamics>
          <damping>0</damping>
          <friction>0</friction>
          <spring_reference>0</spring_reference>
          <spring_stiffness>0</spring_stiffness>
        </dynamics>
      </axis>
    </joint>
    <link name='upper_arm_link'>
      <pose relative_to='shoulder_lift_joint'>0 0 0 0 0 0</pose>
      <inertial>
        <pose>0 0 0.122 0 0 0</pose>
        <mass>3.4199999999999999</mass>
        <inertia>
          <ixx>0.021777126289100002</ixx>
          <ixy>0</ixy>
          <ixz>0</ixz>
          <iyy>0.021777126289100002</iyy>
          <iyz>0</iyz>
          <izz>0.0096187500000000006</izz>
        </inertia>
      </inertial>
      <collision name='upper_arm_link_collision'>
        <pose>0 0 0 0 0 0</pose>
        <geometry>
          <mesh>
            <scale>1 1 1</scale>
            <uri>meshes/collision/upperarm.stl</uri>
          </mesh>
        </geometry>
        <surface>
          <contact>
            <ode/>
          </contact>
          <friction>
            <ode/>
          </friction>
        </surface>
      </collision>
      <visual name='upper_arm_link_visual'>
        <pose>0 0 0 0 0 0</pose>
        <geometry>
          <mesh>
            <scale>1 1 1</scale>
            <uri>meshes/visual/upperarm.dae</uri>
          </mesh>
        </geometry>
      </visual>
      <self_collide>true</self_collide>
    </link>
    <joint name='elbow_joint' type='revolute'>
      <pose relative_to='upper_arm_link'>0 -0.093 0.244 0 0 0</pose>
      <parent>upper_arm_link</parent>
      <child>forearm_link</child>
      <axis>
        <xyz>0 1 0</xyz>
        <limit>
          <lower>-3.1415926535900001</lower>
          <upper>3.1415926535900001</upper>
          <effort>150</effort>
          <velocity>3.1400000000000001</velocity>
        </limit>
        <dynamics>
          <damping>0</damping>
          <friction>0</friction>
          <spring_reference>0</spring_reference>
          <spring_stiffness>0</spring_stiffness>
        </dynamics>
      </axis>
    </joint>
    <link name='forearm_link'>
      <pose relative_to='elbow_joint'>0 0 0 0 0 0</pose>
      <inertial>
        <pose>0 0 0.1065 0 0 0</pose>
        <mass>1.26</mass>
        <inertia>
          <ixx>0.0065356173857500002</ixx>
          <ixy>0</ixy>
          <ixz>0</ixz>
          <iyy>0.0065356173857500002</iyy>
          <iyz>0</iyz>
          <izz>0.00354375</izz>
        </inertia>
      </inertial>
      <collision name='forearm_link_collision'>
        <pose>0 0 0 0 0 0</pose>
        <geometry>
          <mesh>
            <scale>1 1 1</scale>
            <uri>meshes/collision/forearm.stl</uri>
          </mesh>
        </geometry>
        <surface>
          <contact>
            <ode/>
          </contact>
          <friction>
            <ode/>
          </friction>
        </surface>
      </collision>
      <visual name='forearm_link_visual'>
        <pose>0 0 0 0 0 0</pose>
        <geometry>
          <mesh>
            <scale>1 1 1</scale>
            <uri>meshes/visual/forearm.dae</uri>
          </mesh>
        </geometry>
      </visual>
      <self_collide>true</self_collide>
    </link>
    <joint name='wrist_1_joint' type='revolute'>
      <pose relative_to='forearm_link'>0 0 0.213 0 1.570796326794897 0</pose>
      <parent>forearm_link</parent>
      <child>wrist_1_link</child>
      <axis>
        <xyz>0 1 0</xyz>
        <limit>
          <lower>-3.1415926535900001</lower>
          <upper>3.1415926535900001</upper>
          <effort>54</effort>
          <velocity>6.2800000000000002</velocity>
        </limit>
        <dynamics>
          <damping>0</damping>
          <friction>0</friction>
          <spring_reference>0</spring_reference>
          <spring_stiffness>0</spring_stiffness>
        </dynamics>
      </axis>
    </joint>
    <link name='wrist_1_link'>
      <pose relative_to='wrist_1_joint'>0 0 0 0 0 0</pose>
      <inertial>
        <pose>0 0.104 0 0 0 0</pose>
        <mass>0.80000000000000004</mass>
        <inertia>
          <ixx>0.0020849991659999999</ixx>
          <ixy>0</ixy>
          <ixz>0</ixz>
          <iyy>0.0020849991659999999</iyy>
          <iyz>0</iyz>
          <izz>0.0022499999999999998</izz>
        </inertia>
      </inertial>
      <collision name='wrist_1_link_collision'>
        <pose>0 0 0 0 0 0</pose>
        <geometry>
          <mesh>
            <scale>1 1 1</scale>
            <uri>meshes/collision/wrist1.stl</uri>
          </mesh>
        </geometry>
        <surface>
          <contact>
            <ode/>
          </contact>
          <friction>
            <ode/>
          </friction>
        </surface>
      </collision>
      <visual name='wrist_1_link_visual'>
        <pose>0 0 0 0 0 0</pose>
        <geometry>
          <mesh>
            <scale>1 1 1</scale>
            <uri>meshes/visual/wrist1.dae</uri>
          </mesh>
        </geometry>
      </visual>
      <self_collide>true</self_collide>
    </link>
    <joint name='wrist_2_joint' type='revolute'>
      <pose relative_to='wrist_1_link'>0 0.104 0 0 0 0</pose>
      <parent>wrist_1_link</parent>
      <child>wrist_2_link</child>
      <axis>
        <xyz>0 0 1</xyz>
        <limit>
          <lower>-3.1415926535900001</lower>
          <upper>3.1415926535900001</upper>
          <effort>54</effort>
          <velocity>6.2800000000000002</velocity>
        </limit>
        <dynamics>
          <damping>0</damping>
          <friction>0</friction>
          <spring_reference>0</spring_reference>
          <spring_stiffness>0</spring_stiffness>
        </dynamics>
      </axis>
    </joint>
    <link name='wrist_2_link'>
      <pose relative_to='wrist_2_joint'>0 0 0 0 0 0</pose>
      <inertial>
        <pose>0 0 0.08500000000000001 0 0 0</pose>
        <mass>0.80000000000000004</mass>
        <inertia>
          <ixx>0.0020849991659999999</ixx>
          <ixy>0</ixy>
          <ixz>0</ixz>
          <iyy>0.0020849991659999999</iyy>
          <iyz>0</iyz>
          <izz>0.0022499999999999998</izz>
        </inertia>
      </inertial>
      <collision name='wrist_2_link_collision'>
        <pose>0 0 0 0 0 0</pose>
        <geometry>
          <mesh>
            <scale>1 1 1</scale>
            <uri>meshes/collision/wrist2.stl</uri>
          </mesh>
        </geometry>
        <surface>
          <contact>
            <ode/>
          </contact>
          <friction>
            <ode/>
          </friction>
        </surface>
      </collision>
      <visual name='wrist_2_link_visual'>
        <pose>0 0 0 0 0 0</pose>
        <geometry>
          <mesh>
            <scale>1 1 1</scale>
            <uri>meshes/visual/wrist2.dae</uri>
          </mesh>
        </geometry>
      </visual>
      <self_collide>true</self_collide>
    </link>
    <joint name='wrist_3_joint' type='revolute'>
      <pose relative_to='wrist_2_link'>0 0 0.08500000000000001 0 0 0</pose>
      <parent>wrist_2_link</parent>
      <child>wrist_3_link</child>
      <axis>
        <xyz>0 1 0</xyz>
        <limit>
          <lower>-3.1415926535900001</lower>
          <upper>3.1415926535900001</upper>
          <effort>54</effort>
          <velocity>6.2800000000000002</velocity>
        </limit>
        <dynamics>
          <damping>0</damping>
          <friction>0</friction>
          <spring_reference>0</spring_reference>
          <spring_stiffness>0</spring_stiffness>
        </dynamics>
      </axis>
    </joint>
    <link name='wrist_3_link'>
      <pose relative_to='wrist_3_joint'>0 0 0 0 0 0</pose>
      <inertial>
        <pose>0 0.07099999999999999 0 1.57079632679 0 0</pose>
        <mass>0.34999999999999998</mass>
        <inertia>
          <ixx>0.00014104994357999999</ixx>
          <ixy>0</ixy>
          <ixz>0</ixz>
          <iyy>0.00014104994357999999</iyy>
          <iyz>0</iyz>
          <izz>0.00017919999999999999</izz>
        </inertia>
      </inertial>
      <collision name='wrist_3_link_collision'>
        <pose>0 0 0 0 0 0</pose>
        <geometry>
          <mesh>
            <scale>1 1 1</scale>
            <uri>meshes/collision/wrist3.stl</uri>
          </mesh>
        </geometry>
        <surface>
          <contact>
            <ode/>
          </contact>
          <friction>
            <ode/>
          </friction>
        </surface>
      </collision>
      <collision name='wrist_3_link_fixed_joint_lump__ee_link_collision_1'>
        <pose>-4.896777427987331e-14 0.082 0 0 0 1.57079632679</pose>
        <geometry>
          <box>
            <size>0.01 0.01 0.01</size>
          </box>
        </geometry>
        <surface>
          <contact>
            <ode/>
          </contact>
          <friction>
            <ode/>
          </friction>
        </surface>
      </collision>
      <visual name='wrist_3_link_visual'>
        <pose>0 0 0 0 0 0</pose>
        <geometry>
          <mesh>
            <scale>1 1 1</scale>
            <uri>meshes/visual/wrist3.dae</uri>
          </mesh>
        </geometry>
      </visual>
      <self_collide>true</self_collide>
    </link>
    <frame name='base_link-base_fixed_joint' attached_to='base_link'>
      <pose>0 0 0 0 0 3.14159</pose>
    </frame>
    <frame name='base' attached_to='base_link-base_fixed_joint'/>
    <frame name='ee_fixed_joint' attached_to='wrist_3_link'>
      <pose>0 0.092 0 0 -0 1.5708</pose>
    </frame>
    <frame name='ee_link' attached_to='ee_fixed_joint'/>
    <frame name='wrist_3_link-tool0_fixed_joint' attached_to='wrist_3_link'>
      <pose>0 0.092 0 -1.5708 0 0</pose> <!-- transform from wrist_3_link to tool0 -->
    </frame>
    <frame name='tool0' attached_to='wrist_3_link-tool0_fixed_joint'/>

    <!-- Joint controller plugins -->
    <!-- Used values from
    https://github.com/mkrizmancic/franka_gazebo/blob/4a88ce6ca7d3d7bb87bd3fbe91e12873cc42f9b9/config/default.yaml-->
    <plugin filename="ignition-gazebo-joint-position-controller-system" name="ignition::gazebo::systems::JointPositionController">
      <joint_name>shoulder_pan_joint</joint_name>
      <p_gain>50</p_gain>
      <d_gain>20</d_gain>
      <i_gain>0</i_gain>
      <i_min>-1</i_min>
      <i_max>1</i_max>
      <cmd_min>-87</cmd_min>
      <cmd_max>87</cmd_max>
    </plugin>
    <plugin filename="ignition-gazebo-joint-position-controller-system" name="ignition::gazebo::systems::JointPositionController">
      <joint_name>shoulder_lift_joint</joint_name>
      <p_gain>10000</p_gain>
      <d_gain>500</d_gain>
      <i_gain>0</i_gain>
      <i_min>-1</i_min>
      <i_max>1</i_max>
      <cmd_min>-87</cmd_min>
      <cmd_max>87</cmd_max>
    </plugin>
    <plugin filename="ignition-gazebo-joint-position-controller-system" name="ignition::gazebo::systems::JointPositionController">
      <joint_name>elbow_joint</joint_name>
      <p_gain>100</p_gain>
      <d_gain>10</d_gain>
      <i_gain>0</i_gain>
      <i_min>-1</i_min>
      <i_max>1</i_max>
      <cmd_min>-87</cmd_min>
      <cmd_max>87</cmd_max>
    </plugin>
    <plugin filename="ignition-gazebo-joint-position-controller-system" name="ignition::gazebo::systems::JointPositionController">
      <joint_name>wrist_1_joint</joint_name>
      <p_gain>1000</p_gain>
      <d_gain>50</d_gain>
      <i_gain>0</i_gain>
      <i_min>-1</i_min>
      <i_max>1</i_max>
      <cmd_min>-87</cmd_min>
      <cmd_max>87</cmd_max>
    </plugin>
    <plugin filename="ignition-gazebo-joint-position-controller-system" name="ignition::gazebo::systems::JointPositionController">
      <joint_name>wrist_2_joint</joint_name>
      <p_gain>100</p_gain>
      <d_gain>50</d_gain>
      <i_gain>0</i_gain>
      <i_min>-1</i_min>
      <i_max>1</i_max>
      <cmd_min>-12</cmd_min>
      <cmd_max>12</cmd_max>
    </plugin>
    <plugin filename="ignition-gazebo-joint-position-controller-system" name="ignition::gazebo::systems::JointPositionController">
      <joint_name>wrist_3_joint</joint_name>
      <p_gain>100</p_gain>
      <d_gain>10</d_gain>
      <i_gain>0</i_gain>
      <i_min>-1</i_min>
      <i_max>1</i_max>
      <cmd_min>-12</cmd_min>
      <cmd_max>12</cmd_max>
    </plugin>
  </model>
</sdf>
