<sdf version='1.9'>
  <model name='inspire_hand_right'>
    <link name='base'>
      <inertial>
        <pose>0.002526394800594673 -0.001959388838160591 0.06604701239793076 0 0 0</pose>
        <mass>0.14143</mass>
        <inertia>
          <ixx>0.0001228100093982323</ixx>
          <ixy>1.7707912807802509e-06</ixy>
          <ixz>2.1710844039917139e-06</ixz>
          <iyy>7.666296965909826e-05</iyy>
          <iyz>-1.655060404248129e-06</iyz>
          <izz>8.3832020942669507e-05</izz>
        </inertia>
      </inertial>
      <collision name='base_fixed_joint_lump__hand_base_link_collision'>
        <pose>2.283265697344361e-13 8.604441060003354e-08 0.01359999999972781 0 0 3.14159</pose>
        <geometry>
          <cylinder>
            <length>0.027799999999999998</length>
            <radius>0.028000000000000001</radius>
          </cylinder>
        </geometry>
      </collision>
      <collision name='base_fixed_joint_lump__hand_base_link_collision_1'>
        <pose>0.003200000000626708 2.319267187397833e-07 0.03799999999923946 -1.57079 0 3.14159</pose>
        <geometry>
          <box>
            <size>0.0391 0.0202 0.0574</size>
          </box>
        </geometry>
      </collision>
      <collision name='base_fixed_joint_lump__hand_base_link_collision_2'>
        <pose>0.003200000001133726 4.229959246482284e-07 0.06819999999863505 -1.57079 0 3.14159</pose>
        <geometry>
          <box>
            <size>0.0391 0.04 0.0814</size>
          </box>
        </geometry>
      </collision>
      <collision name='base_fixed_joint_lump__hand_base_link_collision_3'>
        <pose>1.814860454994165e-12 6.839265283553608e-07 0.1080999999978365 -1.57079 0 3.14159</pose>
        <geometry>
          <box>
            <size>0.0322 0.04 0.0814</size>
          </box>
        </geometry>
      </collision>
      <collision name='base_fixed_joint_lump__hand_base_link_collision_4'>
        <pose>0.001599918006319443 -0.03089915645450027 0.1340001954952804 -1.57079 0 3.14159</pose>
        <geometry>
          <box>
            <size>0.0125 0.0111 0.0089</size>
          </box>
        </geometry>
      </collision>
      <collision name='base_fixed_joint_lump__hand_base_link_collision_5'>
        <pose>0.001599968689884495 -0.01179915645494978 0.1340000746534979 -1.57079 0 3.14159</pose>
        <geometry>
          <box>
            <size>0.0125 0.0111 0.0089</size>
          </box>
        </geometry>
      </collision>
      <collision name='base_fixed_joint_lump__hand_base_link_collision_6'>
        <pose>0.001600018577372609 0.007000843544607754 0.1339999557097538 -1.57079 0 3.14159</pose>
        <geometry>
          <box>
            <size>0.0125 0.0111 0.0089</size>
          </box>
        </geometry>
      </collision>
      <collision name='base_fixed_joint_lump__hand_base_link_collision_7'>
        <pose>0.00160006952629664 0.02620084354415589 0.1339998342352918 -1.57079 0 3.14159</pose>
        <geometry>
          <box>
            <size>0.0125 0.0111 0.0089</size>
          </box>
        </geometry>
      </collision>
      <visual name='base_fixed_joint_lump__hand_base_link_visual'>
        <pose>0 0 0 -1.57079 0 3.14159</pose>
        <geometry>
          <mesh>
            <scale>1 1 1</scale>
            <uri>meshes/visual/right_base_link.dae</uri>
          </mesh>
        </geometry>
      </visual>
    </link>
    <joint name='index_proximal_joint' type='revolute'>
      <pose relative_to='base'>-0.0002852443716713816 0.03226886455369662 0.1365297958442498 1.605695307179587 2.117582368135751e-22 3.14159</pose>
      <parent>base</parent>
      <child>index_proximal</child>
      <axis>
        <xyz>0 0 1</xyz>
        <limit>
          <lower>0</lower>
          <upper>1.47</upper>
          <effort>1</effort>
          <velocity>0.5</velocity>
        </limit>
        <dynamics>
          <spring_reference>0</spring_reference>
          <spring_stiffness>0</spring_stiffness>
        </dynamics>
      </axis>
    </joint>
    <link name='index_proximal'>
      <pose relative_to='index_proximal_joint'>0 0 0 0 0 0</pose>
      <inertial>
        <pose>0.0012259 0.011942 -0.0060001 0 0 0</pose>
        <mass>0.0042402999999999998</mass>
        <inertia>
          <ixx>6.6232000000000002e-07</ixx>
          <ixy>-1.5775000000000001e-08</ixy>
          <ixz>1.8514999999999999e-12</ixz>
          <iyy>2.1145999999999999e-07</iyy>
          <iyz>-5.0828000000000001e-12</iyz>
          <izz>6.9398000000000002e-07</izz>
        </inertia>
      </inertial>
      <collision name='index_proximal_collision'>
        <pose>0 0 0 0 0 0</pose>
        <geometry>
          <mesh>
            <scale>1 1 1</scale>
            <uri>meshes/collision/right_index_proximal.dae</uri>
          </mesh>
        </geometry>
      </collision>
      <visual name='index_proximal_visual'>
        <pose>0 0 0 0 0 0</pose>
        <geometry>
          <mesh>
            <scale>1 1 1</scale>
            <uri>meshes/visual/right_index_proximal.dae</uri>
          </mesh>
        </geometry>
      </visual>
    </link>
    <joint name='index_intermediate_joint' type='revolute'>
      <pose relative_to='index_proximal'>-0.0026138 0.032026 -0.001 0 0 0</pose>
      <parent>index_proximal</parent>
      <child>index_intermediate</child>
      <axis>
        <xyz>0 0 1</xyz>
        <limit>
          <lower>-0.045449999999999997</lower>
          <upper>1.5600000000000001</upper>
          <effort>1</effort>
          <velocity>0.5</velocity>
        </limit>
        <dynamics>
          <spring_reference>0</spring_reference>
          <spring_stiffness>0</spring_stiffness>
        </dynamics>
      </axis>
    </joint>
    <link name='index_intermediate'>
      <pose relative_to='index_intermediate_joint'>0 0 0 0 0 0</pose>
      <inertial>
        <pose>0.0019697 0.019589 -0.005 0 0 0</pose>
        <mass>0.0045683</mass>
        <inertia>
          <ixx>7.6110999999999996e-07</ixx>
          <ixy>8.7637000000000006e-08</ixy>
          <ixz>-3.7751000000000002e-13</ixz>
          <iyy>9.6076000000000006e-08</iyy>
          <iyz>9.9443999999999995e-13</iyz>
          <izz>7.8179000000000001e-07</izz>
        </inertia>
      </inertial>
      <collision name='index_intermediate_collision'>
        <pose>0 0 0 0 0 0</pose>
        <geometry>
          <mesh>
            <scale>1 1 1</scale>
            <uri>meshes/collision/right_index_intermediate.dae</uri>
          </mesh>
        </geometry>
      </collision>
      <visual name='index_intermediate_visual'>
        <pose>0 0 0 0 0 0</pose>
        <geometry>
          <mesh>
            <scale>1 1 1</scale>
            <uri>meshes/visual/right_index_intermediate.dae</uri>
          </mesh>
        </geometry>
      </visual>
    </link>
    <joint name='middle_proximal_joint' type='revolute'>
      <pose relative_to='base'>-0.000285295633709439 0.01295086816042437 0.1370999180652622 1.570795307179587 0 3.14159</pose>
      <parent>base</parent>
      <child>middle_proximal</child>
      <axis>
        <xyz>0 0 1</xyz>
        <limit>
          <lower>0</lower>
          <upper>1.47</upper>
          <effort>1</effort>
          <velocity>0.5</velocity>
        </limit>
        <dynamics>
          <spring_reference>0</spring_reference>
          <spring_stiffness>0</spring_stiffness>
        </dynamics>
      </axis>
    </joint>
    <link name='middle_proximal'>
      <pose relative_to='middle_proximal_joint'>0 0 0 0 0 0</pose>
      <inertial>
        <pose>0.001297 0.011934 -0.0060001 0 0 0</pose>
        <mass>0.0042402999999999998</mass>
        <inertia>
          <ixx>6.6211000000000004e-07</ixx>
          <ixy>-1.8460999999999999e-08</ixy>
          <ixz>1.8001999999999999e-12</ixz>
          <iyy>2.1166999999999999e-07</iyy>
          <iyz>-6.6808000000000004e-12</iyz>
          <izz>6.9396999999999996e-07</izz>
        </inertia>
      </inertial>
      <collision name='middle_proximal_collision'>
        <pose>0 0 0 0 0 0</pose>
        <geometry>
          <mesh>
            <scale>1 1 1</scale>
            <uri>meshes/collision/right_index_proximal.dae</uri>
          </mesh>
        </geometry>
      </collision>
      <visual name='middle_proximal_visual'>
        <pose>0 0 0 0 0 0</pose>
        <geometry>
          <mesh>
            <scale>1 1 1</scale>
            <uri>meshes/visual/right_index_proximal.dae</uri>
          </mesh>
        </geometry>
      </visual>
    </link>
    <joint name='middle_intermediate_joint' type='revolute'>
      <pose relative_to='middle_proximal'>-0.0024229 0.032041 -0.001 0 0 0</pose>
      <parent>middle_proximal</parent>
      <child>middle_intermediate</child>
      <axis>
        <xyz>0 0 1</xyz>
        <limit>
          <lower>-0.045449999999999997</lower>
          <upper>1.5600000000000001</upper>
          <effort>1</effort>
          <velocity>0.5</velocity>
        </limit>
        <dynamics>
          <spring_reference>0</spring_reference>
          <spring_stiffness>0</spring_stiffness>
        </dynamics>
      </axis>
    </joint>
    <link name='middle_intermediate'>
      <pose relative_to='middle_intermediate_joint'>0 0 0 0 0 0</pose>
      <inertial>
        <pose>0.001921 0.020796 -0.005 0 0 0</pose>
        <mass>0.0050396</mass>
        <inertia>
          <ixx>9.5821999999999991e-07</ixx>
          <ixy>1.1424999999999999e-07</ixy>
          <ixz>-2.4790999999999998e-12</ixz>
          <iyy>1.0646e-07</iyy>
          <iyz>5.9173000000000002e-12</iyz>
          <izz>9.8384000000000005e-07</izz>
        </inertia>
      </inertial>
      <collision name='middle_intermediate_collision'>
        <pose>0 0 0 0 0 0</pose>
        <geometry>
          <mesh>
            <scale>1 1 1</scale>
            <uri>meshes/collision/right_middle_intermediate.dae</uri>
          </mesh>
        </geometry>
      </collision>
      <visual name='middle_intermediate_visual'>
        <pose>0 0 0 0 0 0</pose>
        <geometry>
          <mesh>
            <scale>1 1 1</scale>
            <uri>meshes/visual/right_middle_intermediate.dae</uri>
          </mesh>
        </geometry>
      </visual>
    </link>
    <joint name='pinky_proximal_joint' type='revolute'>
      <pose relative_to='base'>-0.0002853976324172502 -0.02548714063291588 0.1357101612546322 1.46611 0 3.14159</pose>
      <parent>base</parent>
      <child>pinky_proximal</child>
      <axis>
        <xyz>0 0 1</xyz>
        <limit>
          <lower>0</lower>
          <upper>1.47</upper>
          <effort>1</effort>
          <velocity>0.5</velocity>
        </limit>
        <dynamics>
          <spring_reference>0</spring_reference>
          <spring_stiffness>0</spring_stiffness>
        </dynamics>
      </axis>
    </joint>
    <link name='pinky_proximal'>
      <pose relative_to='pinky_proximal_joint'>0 0 0 0 0 0</pose>
      <inertial>
        <pose>0.001297 0.011934 -0.0060001 0 0 0</pose>
        <mass>0.0042402999999999998</mass>
        <inertia>
          <ixx>6.6211000000000004e-07</ixx>
          <ixy>-1.8460999999999999e-08</ixy>
          <ixz>1.6907000000000001e-12</ixz>
          <iyy>2.1166999999999999e-07</iyy>
          <iyz>-6.9334000000000003e-12</iyz>
          <izz>6.9396999999999996e-07</izz>
        </inertia>
      </inertial>
      <collision name='pinky_proximal_collision'>
        <pose>0 0 0 0 0 0</pose>
        <geometry>
          <mesh>
            <scale>1 1 1</scale>
            <uri>meshes/collision/right_index_proximal.dae</uri>
          </mesh>
        </geometry>
      </collision>
      <visual name='pinky_proximal_visual'>
        <pose>0 0 0 0 0 0</pose>
        <geometry>
          <mesh>
            <scale>1 1 1</scale>
            <uri>meshes/visual/right_index_proximal.dae</uri>
          </mesh>
        </geometry>
      </visual>
    </link>
    <joint name='pinky_intermediate_joint' type='revolute'>
      <pose relative_to='pinky_proximal'>-0.0024229 0.032041 -0.001 0 0 0</pose>
      <parent>pinky_proximal</parent>
      <child>pinky_intermediate</child>
      <axis>
        <xyz>0 0 1</xyz>
        <limit>
          <lower>-0.045449999999999997</lower>
          <upper>1.5600000000000001</upper>
          <effort>1</effort>
          <velocity>0.5</velocity>
        </limit>
        <dynamics>
          <spring_reference>0</spring_reference>
          <spring_stiffness>0</spring_stiffness>
        </dynamics>
      </axis>
    </joint>
    <link name='pinky_intermediate'>
      <pose relative_to='pinky_intermediate_joint'>0 0 0 0 0 0</pose>
      <inertial>
        <pose>0.0024748 0.016203 -0.0050031 0 0 0</pose>
        <mass>0.0035996000000000001</mass>
        <inertia>
          <ixx>4.3912999999999999e-07</ixx>
          <ixy>4.1418000000000001e-08</ixy>
          <ixz>3.7168000000000002e-11</ixz>
          <iyy>7.0246999999999994e-08</iyy>
          <iyz>5.8613000000000005e-11</iyz>
          <izz>4.4867000000000001e-07</izz>
        </inertia>
      </inertial>
      <collision name='pinky_intermediate_collision'>
        <pose>0 0 0 0 0 0</pose>
        <geometry>
          <mesh>
            <scale>1 1 1</scale>
            <uri>meshes/collision/right_pinky_intermediate.dae</uri>
          </mesh>
        </geometry>
      </collision>
      <visual name='pinky_intermediate_visual'>
        <pose>0 0 0 0 0 0</pose>
        <geometry>
          <mesh>
            <scale>1 1 1</scale>
            <uri>meshes/visual/right_pinky_intermediate.dae</uri>
          </mesh>
        </geometry>
      </visual>
    </link>
    <joint name='ring_proximal_joint' type='revolute'>
      <pose relative_to='base'>-0.0002853466813502006 -0.006286333041213898 0.1369100397750848 1.51841 0 3.14159</pose>
      <parent>base</parent>
      <child>ring_proximal</child>
      <axis>
        <xyz>0 0 1</xyz>
        <limit>
          <lower>0</lower>
          <upper>1.47</upper>
          <effort>1</effort>
          <velocity>0.5</velocity>
        </limit>
        <dynamics>
          <spring_reference>0</spring_reference>
          <spring_stiffness>0</spring_stiffness>
        </dynamics>
      </axis>
    </joint>
    <link name='ring_proximal'>
      <pose relative_to='ring_proximal_joint'>0 0 0 0 0 0</pose>
      <inertial>
        <pose>0.001297 0.011934 -0.0060002 0 0 0</pose>
        <mass>0.0042402999999999998</mass>
        <inertia>
          <ixx>6.6211000000000004e-07</ixx>
          <ixy>-1.8460999999999999e-08</ixy>
          <ixz>1.5792999999999999e-12</ixz>
          <iyy>2.1166999999999999e-07</iyy>
          <iyz>-6.6868000000000001e-12</iyz>
          <izz>6.9396999999999996e-07</izz>
        </inertia>
      </inertial>
      <collision name='ring_proximal_collision'>
        <pose>0 0 0 0 0 0</pose>
        <geometry>
          <mesh>
            <scale>1 1 1</scale>
            <uri>meshes/collision/right_index_proximal.dae</uri>
          </mesh>
        </geometry>
      </collision>
      <visual name='ring_proximal_visual'>
        <pose>0 0 0 0 0 0</pose>
        <geometry>
          <mesh>
            <scale>1 1 1</scale>
            <uri>meshes/visual/right_index_proximal.dae</uri>
          </mesh>
        </geometry>
      </visual>
    </link>
    <joint name='ring_intermediate_joint' type='revolute'>
      <pose relative_to='ring_proximal'>-0.0024229 0.032041 -0.001 0 0 0</pose>
      <parent>ring_proximal</parent>
      <child>ring_intermediate</child>
      <axis>
        <xyz>0 0 1</xyz>
        <limit>
          <lower>-0.045449999999999997</lower>
          <upper>1.5600000000000001</upper>
          <effort>1</effort>
          <velocity>0.5</velocity>
        </limit>
        <dynamics>
          <spring_reference>0</spring_reference>
          <spring_stiffness>0</spring_stiffness>
        </dynamics>
      </axis>
    </joint>
    <link name='ring_intermediate'>
      <pose relative_to='ring_intermediate_joint'>0 0 0 0 0 0</pose>
      <inertial>
        <pose>0.0021753 0.019567 -0.005 0 0 0</pose>
        <mass>0.0045683</mass>
        <inertia>
          <ixx>7.6285999999999999e-07</ixx>
          <ixy>8.0634999999999994e-08</ixy>
          <ixz>-6.1561999999999996e-13</ixz>
          <iyy>9.4310000000000002e-08</iyy>
          <iyz>5.8619000000000005e-13</iyz>
          <izz>7.8176999999999999e-07</izz>
        </inertia>
      </inertial>
      <collision name='ring_intermediate_collision'>
        <pose>0 0 0 0 0 0</pose>
        <geometry>
          <mesh>
            <scale>1 1 1</scale>
            <uri>meshes/collision/right_index_intermediate.dae</uri>
          </mesh>
        </geometry>
      </collision>
      <visual name='ring_intermediate_visual'>
        <pose>0 0 0 0 0 0</pose>
        <geometry>
          <mesh>
            <scale>1 1 1</scale>
            <uri>meshes/visual/right_index_intermediate.dae</uri>
          </mesh>
        </geometry>
      </visual>
    </link>
    <joint name='thumb_proximal_yaw_joint' type='revolute'>
      <pose relative_to='base'>0.01696005426701167 0.02045039217616321 0.0690998706156614 3.673181863714987e-06 -6.326794896680421e-06 -1.570795307179586</pose>
      <parent>base</parent>
      <child>thumb_proximal_base</child>
      <axis>
        <xyz>0 0 -1</xyz>
        <limit>
          <lower>0</lower>
          <upper>1.3080000000000001</upper>
          <effort>1</effort>
          <velocity>0.5</velocity>
        </limit>
        <dynamics>
          <spring_reference>0</spring_reference>
          <spring_stiffness>0</spring_stiffness>
        </dynamics>
      </axis>
    </joint>
    <link name='thumb_proximal_base'>
      <pose relative_to='thumb_proximal_yaw_joint'>0 0 0 0 0 0</pose>
      <inertial>
        <pose>-0.0048064 0.0009382 -0.00757 0 0 0</pose>
        <mass>0.0018868999999999999</mass>
        <inertia>
          <ixx>5.8159999999999999e-08</ixx>
          <ixy>1.4539e-08</ixy>
          <ixz>4.4910000000000003e-09</ixz>
          <iyy>7.9161000000000003e-08</iyy>
          <iyz>-1.8727e-09</iyz>
          <izz>6.7433000000000006e-08</izz>
        </inertia>
      </inertial>
      <collision name='thumb_proximal_base_collision'>
        <pose>0 0 0 0 0 0</pose>
        <geometry>
          <mesh>
            <scale>1 1 1</scale>
            <uri>meshes/collision/right_thumb_proximal_base.dae</uri>
          </mesh>
        </geometry>
      </collision>
      <visual name='thumb_proximal_base_visual'>
        <pose>0 0 0 0 0 0</pose>
        <geometry>
          <mesh>
            <scale>1 1 1</scale>
            <uri>meshes/visual/right_thumb_proximal_base.dae</uri>
          </mesh>
        </geometry>
      </visual>
    </link>
    <joint name='thumb_proximal_pitch_joint' type='revolute'>
      <pose relative_to='thumb_proximal_base'>-0.008809900000000001 0.010892 -0.00925 1.5708 0 2.8587</pose>
      <parent>thumb_proximal_base</parent>
      <child>thumb_proximal</child>
      <axis>
        <xyz>0 0 1</xyz>
        <limit>
          <lower>0</lower>
          <upper>0.59999999999999998</upper>
          <effort>1</effort>
          <velocity>0.5</velocity>
        </limit>
        <dynamics>
          <spring_reference>0</spring_reference>
          <spring_stiffness>0</spring_stiffness>
        </dynamics>
      </axis>
    </joint>
    <link name='thumb_proximal'>
      <pose relative_to='thumb_proximal_pitch_joint'>0 0 0 0 0 0</pose>
      <inertial>
        <pose>0.021932 0.012785 -0.0080386 0 0 0</pose>
        <mass>0.0066074999999999997</mass>
        <inertia>
          <ixx>1.5685999999999999e-06</ixx>
          <ixy>-7.8296000000000002e-07</ixy>
          <ixz>8.9142999999999999e-10</ixz>
          <iyy>1.7352999999999999e-06</iyy>
          <iyz>-1.0190999999999999e-09</iyz>
          <izz>2.7860000000000001e-06</izz>
        </inertia>
      </inertial>
      <collision name='thumb_proximal_collision'>
        <pose>0 0 0 0 0 0</pose>
        <geometry>
          <mesh>
            <scale>1 1 1</scale>
            <uri>meshes/collision/right_thumb_proximal.dae</uri>
          </mesh>
        </geometry>
      </collision>
      <visual name='thumb_proximal_visual'>
        <pose>0 0 0 0 0 0</pose>
        <geometry>
          <mesh>
            <scale>1 1 1</scale>
            <uri>meshes/visual/right_thumb_proximal.dae</uri>
          </mesh>
        </geometry>
      </visual>
    </link>
    <joint name='thumb_intermediate_joint' type='revolute'>
      <pose relative_to='thumb_proximal'>0.04407 0.034553 -0.0008 0 0 0</pose>
      <parent>thumb_proximal</parent>
      <child>thumb_intermediate</child>
      <axis>
        <xyz>0 0 1</xyz>
        <limit>
          <lower>0</lower>
          <upper>0.80000000000000004</upper>
          <effort>1</effort>
          <velocity>0.5</velocity>
        </limit>
        <dynamics>
          <spring_reference>0</spring_reference>
          <spring_stiffness>0</spring_stiffness>
        </dynamics>
      </axis>
    </joint>
    <link name='thumb_intermediate'>
      <pose relative_to='thumb_intermediate_joint'>0 0 0 0 0 0</pose>
      <inertial>
        <pose>0.009554399999999999 -0.0016282 -0.0071997 0 0 0</pose>
        <mass>0.0037847000000000002</mass>
        <inertia>
          <ixx>3.6981e-07</ixx>
          <ixy>-9.8581000000000001e-08</ixy>
          <ixz>-4.7469000000000003e-12</ixz>
          <iyy>3.2393999999999997e-07</iyy>
          <iyz>1.0939e-12</iyz>
          <izz>4.6530999999999998e-07</izz>
        </inertia>
      </inertial>
      <collision name='thumb_intermediate_collision'>
        <pose>0 0 0 0 0 0</pose>
        <geometry>
          <mesh>
            <scale>1 1 1</scale>
            <uri>meshes/collision/right_thumb_intermediate.dae</uri>
          </mesh>
        </geometry>
      </collision>
      <visual name='thumb_intermediate_visual'>
        <pose>0 0 0 0 0 0</pose>
        <geometry>
          <mesh>
            <scale>1 1 1</scale>
            <uri>meshes/visual/right_thumb_intermediate.dae</uri>
          </mesh>
        </geometry>
      </visual>
    </link>
    <joint name='thumb_distal_joint' type='revolute'>
      <pose relative_to='thumb_intermediate'>0.020248 0.010156 -0.0012 0 0 0</pose>
      <parent>thumb_intermediate</parent>
      <child>thumb_distal</child>
      <axis>
        <xyz>0 0 1</xyz>
        <limit>
          <lower>0</lower>
          <upper>0.40000000000000002</upper>
          <effort>1</effort>
          <velocity>0.5</velocity>
        </limit>
        <dynamics>
          <spring_reference>0</spring_reference>
          <spring_stiffness>0</spring_stiffness>
        </dynamics>
      </axis>
    </joint>
    <link name='thumb_distal'>
      <pose relative_to='thumb_distal_joint'>0 0 0 0 0 0</pose>
      <inertial>
        <pose>0.0092888 0.0049529 -0.0060033 0 0 0</pose>
        <mass>0.0033441</mass>
        <inertia>
          <ixx>1.3631999999999999e-07</ixx>
          <ixy>-5.6787999999999999e-08</ixy>
          <ixz>-9.2763999999999994e-11</ixz>
          <iyy>1.4051999999999999e-07</iyy>
          <iyz>-1.2283e-10</iyz>
          <izz>2.0025999999999999e-07</izz>
        </inertia>
      </inertial>
      <collision name='thumb_distal_collision'>
        <pose>0 0 0 0 0 0</pose>
        <geometry>
          <mesh>
            <scale>1 1 1</scale>
            <uri>meshes/collision/right_thumb_distal.dae</uri>
          </mesh>
        </geometry>
      </collision>
      <visual name='thumb_distal_visual'>
        <pose>0 0 0 0 0 0</pose>
        <geometry>
          <mesh>
            <scale>1 1 1</scale>
            <uri>meshes/visual/right_thumb_distal.dae</uri>
          </mesh>
        </geometry>
      </visual>
    </link>
    <frame name='base_joint' attached_to='base'>
      <pose>0 0 0 -1.57079 -0 3.14159</pose>
    </frame>
    <frame name='hand_base_link' attached_to='base_joint'/>
    <frame name='index_tip_joint' attached_to='index_intermediate'>
      <pose>-0.0008 0.045 -0.005 0 -0 0</pose>
    </frame>
    <frame name='index_tip' attached_to='index_tip_joint'/>
    <frame name='middle_tip_joint' attached_to='middle_intermediate'>
      <pose>-0.001 0.048 -0.005 0 -0 0</pose>
    </frame>
    <frame name='middle_tip' attached_to='middle_tip_joint'/>
    <frame name='pinky_tip_joint' attached_to='pinky_intermediate'>
      <pose>-0.0008 0.037 -0.005 0 -0 0</pose>
    </frame>
    <frame name='pinky_tip' attached_to='pinky_tip_joint'/>
    <frame name='ring_tip_joint' attached_to='ring_intermediate'>
      <pose>-0.0008 0.045 -0.005 0 -0 0</pose>
    </frame>
    <frame name='ring_tip' attached_to='ring_tip_joint'/>
    <frame name='thumb_tip_joint' attached_to='thumb_distal'>
      <pose>0.0202 0.014 -0.006 0 -0 0</pose>
    </frame>
    <frame name='thumb_tip' attached_to='thumb_tip_joint'/>
  </model>
</sdf>
